Workbook
Name ene_25: 'TABLA ESTAD RESUL 2025'!$E$80:$K$80

Sheet ESFA feb 2025
B2: URBANIZACION MONTEVERDI P.H. NIT 900.317.187.5
B4: ESTADO DE LA SITUACION FINANCIERA COMPARATIVO: **ENERO 2025-FEBRERO DE 2025*
B6: ACTIVO | C6: 28/02//2025 | E6: 45688 | G6: DIF. $ | H6: DIF. %
B8: EFECTIVO Y SUS EQUIVALENTES
B9: CAJA MENOR | C9: 200000 | E9: 200000 | G9: =-C9+E9 -> 0 | H9: =+G9/C9 -> 0
B10: BANCOLOMBIA CUENTA DE OPERACIÓN | C10: 17827328 | E10: 18836449 | G10: =-C10+E10 -> 1009121.3 | H10: =+G10/C10 -> 0.056605302
C11: =SUM(C9:C10) -> 18027328 | E11: =SUM(E9:E10) -> 19036449 | G11: =SUM(G9:G10) -> 1009121.3 | H11: =+G11/C11 -> 0.055977308
B13: EFECTIVO RESTRINGIDO
B14: INVERSIONES
B15: INVERSION CDT | C15: 0 | E15: 0
B16: FIDUCUENTA BANCOLOMBIA | C16: 8477538.3 | E16: 8425444.3 | G16: =-C16+E16 -> -52094.04 | H16: =+G16/C16 -> -0.0061449489
C17: =SUM(C15:C16) -> 8477538.3 | E17: =SUM(E15:E16) -> 8425444.3 | G17: =-C17+E17 -> -52094.04 | H17: =+G17/C17 -> -0.0061449489
B19: CUENTAS POR COBRAR
B21: DEUDORES CORRIENTES
B22: COPROPIETARIOS | C22: 5984340 | E22: 4645234 | G22: =+E22-C22 -> -1339106 | H22: =+G22/C22 -> -0.22376837
B23: CONSIGNACIONES POR IDENTIFICAR | C23: 0 | E23: 0 | G23: =+E23-C23 -> 0 | H23: 0
C24: =SUM(C22:C23) -> 5984340 | E24: =SUM(E22:E23) -> 4645234 | G24: =SUM(G22:G23) -> -1339106 | H24: =+G24/C24 -> -0.22376837
B26: ANTICIPO PROVEEDORES | C26: 0 | E26: 0 | G26: =+E26-C26 -> 0 | H26: 0
B27: ANTICIPO OBRA TALUD-TUBERIAS | C27: 0 | E27: 0 | G27: =+E27-C27 -> 0
B28: DEUDORES VARIOS | C28: 50146 | E28: 33310
G29: =+E29-C29 -> 0
B30: GASTOS PAGADOS POR ANTICIPADO
B31: POLIZA SEGURO | C31: 452464 | E31: =+[1]Datos!$D$24/2 -> 1357394 | G31: =+E31-C31 -> 904930 | H31: =+G31/C31 -> 2.0000044
B33: TOTAL ACTIVO | C33: =+C11+C17+C24+C26+C31+C27+C28 -> 32991816 | E33: =+E11+E17+E24+E26+E31+E27+E28 -> 33497832 | G33: =-C33+E33 -> 506015.26 | H33: =+G33/C33 -> 0.015337599
B36: PASIVO
B38: CUENTAS POR PAGAR
B39: COSTOS Y GASTOS POR PAGAR | C39: =973636+471300 -> 1444936 | E39: =541510+488080 -> 1029590 | G39: =+E39-C39 -> -415346 | H39: =+G39/C39 -> -0.28744941
B40: RETENCION IMPUESTOS | C40: 97774.06 | E40: 299010 | G40: =-C40+E40 -> 201235.94 | H40: =+G40/C40 -> 2.0581731
B41: RETEICA | C41: 159977.82 | E41: 75083
C42: =SUM(C39:C41) -> 1702687.9 | E42: =SUM(E39:E41) -> 1403683 | G42: =SUM(G39:G40) -> -214110.06 | H42: =+G42/C42 -> -0.12574827
B43: PASIVOS DIFERIDOS
B44: INGRESOS RECIBIDOS DE TERCEROS
B45: CUOTA EXTRA 2022-RECONOCIMIENTO SEGURO | C45: 7425682 | E45: 7425682
B46: CUOTA EXTRA 2023 | C46: 8550122 | E46: 8550122 | G46: =-C46+E46 -> 0 | H46: =+G46/C46 -> 0
B47: REINVERSIÓN 2023 | C47: 3837291 | E47: 3837291 | G47: =-C47+E47 -> 0 | H47: =+G47/C47 -> 0
B48: CUOTA EXTRA 2024 | C48: =-[1]Datos!$G$61 -> 44870833 | E48: =-[1]Datos!$G$61 -> 44870833 | G48: =-C48+E48 -> 0
B49: TOTAL PASIVOS DIFERIDOS | C49: =SUM(C45:C48) -> 64683928 | E49: =SUM(E45:E48) -> 64683928 | G49: =SUM(G46:G47) -> 0 | H49: =+G49/C49 -> 0
B51: OTROS PASIVOS
B52: PROVISIÓN GASTO VIGILANCIA | C52: 0 | E52: 1598989 | G52: =+E52-C52 -> 1598989 | H52: 0
B53: TOTAL OTROS PASIVOS | C53: =SUM(C52:C52) -> 0 | E53: =SUM(E52:E52) -> 1598989 | G53: =SUM(G52:G52) -> 1598989 | H53: 0
...

Sheet ESFA abril 2025
B2: URBANIZACION MONTEVERDI P.H. NIT 900.317.187.5
B4: ESTADO DE LA SITUACION FINANCIERA COMPARATIVO: *MARZO 2025-ABRIL 2025*
B6: ACTIVO | C6: 28/04//2025 | E6: 28/03//2025 | G6: DIF. $ | H6: DIF. %
B8: EFECTIVO Y SUS EQUIVALENTES
B9: CAJA MENOR | C9: 200000 | E9: 200000 | G9: =-C9+E9 -> 0 | H9: =+G9/C9 -> 0
B10: BANCOLOMBIA CUENTA DE OPERACIÓN | C10: 16236254 | E10: 16432366 | G10: =-C10+E10 -> 196112.1 | H10: =+G10/C10 -> 0.012078654
C11: =SUM(C9:C10) -> 16436254 | E11: =SUM(E9:E10) -> 16632366 | G11: =SUM(G9:G10) -> 196112.1 | H11: =+G11/C11 -> 0.011931679
B12: EFECTIVO RESTRINGIDO
B13: INVERSIONES
B14: INVERSION CDT | C14: 0 | E14: 0
B15: FIDUCUENTA BANCOLOMBIA | C15: 8594287.8 | E15: 8534559.7 | G15: =-C15+E15 -> -59728.13 | H15: =+G15/C15 -> -0.0069497475
C16: =SUM(C14:C15) -> 8594287.8 | E16: =SUM(E14:E15) -> 8534559.7 | G16: =-C16+E16 -> -59728.13 | H16: =+G16/C16 -> -0.0069497475
B18: CUENTAS POR COBRAR
B20: DEUDORES CORRIENTES
B21: COPROPIETARIOS | C21: 4269712 | E21: 4129452 | G21: =+E21-C21 -> -140260 | H21: =+G21/C21 -> -0.032849991
B22: CONSIGNACIONES POR IDENTIFICAR | C22: 0 | E22: 0 | G22: =+E22-C22 -> 0 | H22: 0
C23: =SUM(C21:C22) -> 4269712 | E23: =SUM(E21:E22) -> 4129452 | G23: =SUM(G21:G22) -> -140260 | H23: =+G23/C23 -> -0.032849991
B25: ANTICIPO PROVEEDORES | C25: 0 | E25: 0 | G25: =+E25-C25 -> 0 | H25: 0
B26: ANTICIPO OBRA TALUD-TUBERIAS | C26: 0 | E26: 0 | G26: =+E26-C26 -> 0
B27: DEUDORES VARIOS | C27: 440118 | E27: 38070
G28: =+E28-C28 -> 0
B29: GASTOS PAGADOS POR ANTICIPADO
B30: POLIZA SEGURO | C30: 15358191 | E30: 16844468 | G30: =+E30-C30 -> 1486277 | H30: =+G30/C30 -> 0.096774223
B32: TOTAL ACTIVO | C32: =+C11+C16+C23+C25+C30+C26+C27 -> 45098563 | E32: =+E11+E16+E23+E25+E30+E26+E27 -> 46178916 | G32: =-C32+E32 -> 1080353 | H32: =+G32/C32 -> 0.023955375
C33: 28/04//2025 | E33: 28/03//2025 | G33: DIF. $ | H33: DIF. %
B34: PASIVO
B36: CUENTAS POR PAGAR
B37: COSTOS Y GASTOS POR PAGAR | C37: =-1359+6715424 -> 6714065 | E37: 14432437 | G37: =+E37-C37 -> 7718372 | H37: =+G37/C37 -> 1.1495826
B38: RETENCION IMPUESTOS | C38: 63720.06 | E38: 90156.56 | G38: =-C38+E38 -> 26436.5 | H38: =+G38/C38 -> 0.41488505
B39: RETEICA | C39: 103730.82 | E39: 47884.82
C40: =SUM(C37:C39) -> 6881515.9 | E40: =SUM(E37:E39) -> 14570478 | G40: =SUM(G37:G38) -> 7744808.5 | H40: =+G40/C40 -> 1.1254509
B41: PASIVOS DIFERIDOS
B42: INGRESOS RECIBIDOS DE TERCEROS
B43: CUOTA EXTRA 2022-RECONOCIMIENTO SEGURO | C43: 0 | E43: 7425682
B44: CUOTA EXTRA 2023 | C44: 0 | E44: 8550122 | G44: =-C44+E44 -> 8550122 | H44: NA
B45: REINVERSIÓN 2023 | C45: 0 | E45: 3837291 | G45: =-C45+E45 -> 3837291 | H45: NA
B46: CUOTA EXTRA 2024 | C46: 21864370 | E46: =-[1]Datos!$G$61 -> 44870833 | G46: =-C46+E46 -> 23006464
B47: TOTAL PASIVOS DIFERIDOS | C47: =SUM(C43:C46) -> 21864370 | E47: =SUM(E43:E46) -> 64683928 | G47: =SUM(G44:G45) -> 12387413 | H47: =+G47/C47 -> 0.56655706
B49: OTROS PASIVOS
B50: PROVISIÓN GASTO VIGILANCIA | C50: 0 | E50: 0 | G50: =+E50-C50 -> 0 | H50: 0
...

Sheet GRAFICOS ESFA 2025

Sheet ESFA AGOST 2025
B2: URBANIZACION MONTEVERDI P.H. NIT 900.317.187.5
B4: ESTADO DE LA SITUACION FINANCIERA COMPARATIVO: *AGOSTO 2025-JULIO*
B6: ACTIVO | C6: 45900 | E6: 31/07//2025 | G6: DIF. $ | H6: DIF. %
B8: EFECTIVO Y SUS EQUIVALENTES
B9: CAJA MENOR | C9: 200000 | E9: 200000 | G9: =-C9+E9 -> 0 | H9: =+G9/C9 -> 0
B10: BANCOLOMBIA CUENTA DE OPERACIÓN | C10: =+V41 -> 50572213 | E10: 50775681 | G10: =-C10+E10 -> 203467.92 | H10: =+G10/C10 -> 0.0040233145
C11: =SUM(C9:C10) -> 50772213 | E11: 50975681 | G11: =SUM(G9:G10) -> 203467.92 | H11: =+G11/C11 -> 0.0040074661
B12: EFECTIVO RESTRINGIDO
B13: INVERSIONES
B14: INVERSION CDT | C14: 0 | E14: 0
B15: FIDUCUENTA BANCOLOMBIA | C15: =+V42 -> 10916890 | E15: 10852428 | G15: =-C15+E15 -> -64462.02 | H15: =+G15/C15 -> -0.0059047971
C16: =SUM(C14:C15) -> 10916890 | E16: 10852428 | G16: =-C16+E16 -> -64462.02 | H16: =+G16/C16 -> -0.0059047971
B18: CUENTAS POR COBRAR
B20: DEUDORES CORRIENTES
B21: COPROPIETARIOS | C21: =+V51 -> 14428308 | E21: 8689091 | G21: =+E21-C21 -> -5739217 | H21: =+G21/C21 -> -0.39777478 | R21: =+C32-V35 -> 0
B22: CONSIGNACIONES POR IDENTIFICAR | C22: =-408000 -> -408000 | E22: -408000 | G22: =+E22-C22 -> 0 | H22: 0
C23: =SUM(C21:C22) -> 14020308 | E23: 8281091 | G23: =SUM(G21:G22) -> -5739217 | H23: =+G23/C23 -> -0.40935028
B25: ANTICIPO PROVEEDORES | C25: 0 | E25: 0 | G25: =+E25-C25 -> 0 | H25: 0
B26: ANTICIPO OBRA TALUD-TUBERIAS | C26: 0 | E26: 0 | G26: =+E26-C26 -> 0
B27: DEUDORES VARIOS | C27: =+V47 -> 6688000 | E27: 3232000
G28: =+E28-C28 -> 0
B29: GASTOS PAGADOS POR ANTICIPADO
B30: POLIZA SEGURO | C30: =+V54 -> 9541969 | E30: 10985284 | G30: =+E30-C30 -> 1443315 | H30: =+G30/C30 -> 0.15125966
B32: TOTAL ACTIVO | C32: =+C11+C16+C23+C25+C30+C26+C27 -> 91939380 | E32: 84326484 | G32: =-C32+E32 -> -7612896.1 | H32: =+G32/C32 -> -0.082803431 | Q32: CR URBANIZACION MONTEVERDI P.H. - 900.317.187-5
Q33: Balance de Prueba por Cuenta (Normal) Ago-31-2025
B34: PASIVO | Q34: Cuenta | R34: Nombre | S34: Saldo Anterior | T34: Débitos | U34: Créditos | V34: Nuevo Saldo
Q35: 1 | R35: ACTIVOS | S35: 84326484 | T35: 73041704 | U35: 65428808 | V35: 91939380
B36: CUENTAS POR PAGAR | Q36: 11 | R36: DISPONIBLE | S36: 50567681 | T36: 32097502 | U36: 31892970 | V36: 50772213
B37: COSTOS Y GASTOS POR PAGAR | C37: =-V59 -> 677548 | E37: 677548 | G37: =+E37-C37 -> 0 | H37: =+G37/C37 -> 0 | Q37: 1105 | R37: CAJA | S37: 200000 | T37: 0 | U37: 0 | V37: 200000
B38: RETENCION IMPUESTOS | C38: =-V64 -> 135159.06 | E38: 274160.06 | G38: =-C38+E38 -> 139001 | H38: =+G38/C38 -> 1.0284253 | Q38: 110510 | R38: CAJAS MENORES | S38: 200000 | T38: 0 | U38: 0 | V38: 200000
B39: RETEICA | C39: 0 | E39: 0 | Q39: 1120 | R39: CUENTAS DE AHORRO | S39: 50367681 | T39: 32097502 | U39: 31892970 | V39: 50572213
C40: =SUM(C37:C39) -> 812707.06 | E40: 951708.06 | G40: =SUM(G37:G38) -> 139001 | H40: =+G40/C40 -> 0.17103457 | Q40: 112005 | R40: BANCOS | S40: 50367681 | T40: 32097502 | U40: 31892970 | V40: 50572213
B41: PASIVOS DIFERIDOS | Q41: 11200501 | R41: BANCOLOMBIA CTA 436-544512-07 | S41: 50367681 | T41: 32097502 | U41: 31892970 | V41: 50572213
B42: INGRESOS RECIBIDOS DE TERCEROS | J42: DECISIONES ASAMBLEA | Q42: 12 | R42: INVERSIONES | S42: 10852428 | T42: 64462.02 | U42: 0 | V42: 10916890
B43: CUOTA EXTRA 2022-RECONOCIMIENTO SEGURO | C43: 0 | E43: 0 | J43: GASTOS NO PRESUPUESTADOS X DEFINIR TALUD | K43: =-49920464 -> -49920464 | M43: 31805050 | Q43: 1245 | R43: DERECHOS FIDUCIARIOS | S43: 10852428 | T43: 64462.02 | U43: 0 | V43: 10916890
B44: CUOTA EXTRA 2023 | C44: 8550122 | E44: 8550122 | G44: =-C44+E44 -> 0 | H44: NA | J44: DEFICIT PPTAL 2023 | K44: -893269.33 | M44: -248452.74 | Q44: 124505 | R44: INVERSION MONEDA NACIONAL | S44: 10852428 | T44: 64462.02 | U44: 0 | V44: 10916890
B45: REINVERSIÓN 2023 | C45: 0 | E45: 0 | G45: =-C45+E45 -> 0 | H45: NA | J45: TOTAL A CUBRIR | K45: =SUM(K43:K44) -> -50813733 | M45: -8550122 | Q45: 13 | R45: DEUDORES | S45: 11921091 | T45: 40879740 | U45: 32092523 | V45: 20708308
B46: CUOTA EXTRA 2024 | C46: 44870845 | E46: 44870845 | G46: =-C46+E46 -> 0 | J46: CUBRIR ASI SEGÚN DECISIÓN ASAMBLEA | M46: =SUM(M43:M45) -> 23006475 | N46: =+M46+E46 -> 67877320 | Q46: 1330 | R46: ANTICIPOS Y AVANCES A CONTRATI | S46: 3232000 | T46: 3456000 | U46: 0 | V46: 6688000
B47: CUOTA EXTRA 2025 | C47: =-V86 -> 14999996 | E47: 7500003 | G47: =-C47+E47 -> -7499993 | J47: CUOTA EXTRA 2022-RECONOCIMIENTO SEGURO | K47: 7425682 | Q47: 133010 | R47: A CONTRATISTAS | S47: 3232000 | T47: 3456000 | U47: 0 | V47: 6688000
B48: TOTAL PASIVOS DIFERIDOS | C48: =SUM(C43:C47) -> 68420963 | E48: 60920970 | G48: =SUM(G44:G45) -> 0 | H48: =+G48/C48 -> 0 | J48: CUOTA EXTRA 2023 | K48: 8550122 | Q48: 13301005 | R48: CONTRATOS ZONAS COMUNES | S48: 3232000 | T48: 3456000 | U48: 0 | V48: 6688000
...

Sheet TABLA ESFA 2025
A1: CR URBANIZACION MONTEVERDI P.H. - 900.317.187-5
A2: ESTADO DE SITUACION FINANCIERA AÑO 2025
A3: ACTIVOS
B4: Enero | C4: Febrero | D4: Marzo | E4: Abril | G4: Mayo | I4: Junio | K4: Julio | M4: Agosto | N4: Septiembre | O4: Octubre | P4: Noviembre | Q4: Diciembre
A5: Efectivo y sus equivalentes | B5: ='ESFA feb 2025'!E11 -> 19036449 | C5: ='ESFA feb 2025'!C11 -> 18027328 | D5: ='ESFA abril 2025'!E11 -> 16632366 | E5: ='ESFA abril 2025'!C11 -> 16436254 | G5: ='ESFA MAY 2025'!C11 -> 52872061 | I5: ='ESFA JUN 2025'!C11 -> 48166179 | K5: ='ESFA JUL 2025'!C11 -> 50975681 | M5: ='ESFA AGOST 2025'!C11 -> 50772213
A7: Fiducuenta Bancolombia | B7: ='ESFA feb 2025'!E16 -> 8425444.3 | C7: ='ESFA feb 2025'!C17 -> 8477538.3 | D7: ='ESFA abril 2025'!E16 -> 8534559.7 | E7: ='ESFA abril 2025'!C15 -> 8594287.8 | G7: ='ESFA MAY 2025'!C15 -> 8658779.9 | I7: ='ESFA JUN 2025'!C15 -> 10764304 | K7: ='ESFA JUL 2025'!C16 -> 10852428 | M7: ='ESFA AGOST 2025'!C16 -> 10916890
A9: CXC Administración | B9: ='ESFA feb 2025'!E22 -> 4645234 | C9: ='ESFA feb 2025'!C22 -> 5984340 | D9: ='ESFA abril 2025'!E23 -> 4129452 | E9: ='ESFA abril 2025'!C21 -> 4269712 | G9: ='ESFA MAY 2025'!C21 -> 3942142 | I9: ='ESFA JUN 2025'!C21 -> 11341985 | K9: ='ESFA JUL 2025'!C21 -> 8689091 | M9: ='ESFA AGOST 2025'!C21 -> 14428308
A11: Pagos sin identificar | B11: -503652 | C11: =[4]ESFA!E22 -> -503652 | D11: 0 | E11: 0 | K11: ='ESFA JUL 2025'!C22 -> -408000 | M11: ='ESFA AGOST 2025'!C22 -> -408000
A13: Deudores varios | B13: ='ESFA feb 2025'!E28 -> 33310 | C13: ='ESFA feb 2025'!C28 -> 50146 | D13: ='ESFA abril 2025'!E27 -> 38070 | E13: ='ESFA abril 2025'!C27 -> 440118 | G13: ='ESFA MAY 2025'!C27 -> 0 | K13: ='ESFA JUL 2025'!C27 -> 3232000 | M13: ='ESFA AGOST 2025'!C27 -> 6688000
A15: Gasto por anticipado póliza seguros | B15: ='ESFA feb 2025'!E31 -> 1357394 | C15: ='ESFA feb 2025'!C31 -> 452464 | D15: ='ESFA abril 2025'!E30 -> 16844468 | E15: ='ESFA abril 2025'!C30 -> 15358191 | G15: ='ESFA MAY 2025'!C30 -> 13871914 | I15: ='ESFA JUN 2025'!C30 -> 12428599 | K15: ='ESFA JUL 2025'!C30 -> 10985284 | M15: ='ESFA AGOST 2025'!C30 -> 9541969
E16: =SUM(E5:E16) -> 0
A17: TOTAL ACTIVO | B17: =SUM(B5:B15) -> 32994180 | C17: =SUM(C5:C16) -> 32488164 | D17: =SUM(D5:D16) -> 46178916 | E17: =E5+E7+E9+E13+E15 -> 45098563 | G17: =G5+G7+G9+G13+G15 -> 79344897 | I17: ='ESFA JUN 2025'!C32 -> 82701066 | K17: ='ESFA JUL 2025'!C32 -> 84326484 | M17: =++M5+M7+M9+M11 -> 75709411
A21: PASIVOS
B22: Enero | C22: Febrero | D22: Marzo | E22: Abril | G22: Mayo | I22: Junio | K22: Julio | M22: Agosto
A23: CXP Gastos | B23: ='ESFA feb 2025'!E39 -> 1029590 | C23: ='ESFA feb 2025'!C39 -> 1444936 | D23: ='ESFA abril 2025'!E37 -> 14432437 | E23: ='ESFA abril 2025'!C37 -> 6714065 | G23: ='ESFA MAY 2025'!C37 -> 534252 | I23: ='ESFA JUN 2025'!C37 -> 727051 | K23: ='ESFA JUL 2025'!C37 -> 677548 | M23: ='ESFA AGOST 2025'!C37 -> 677548
A25: CXP | C25: 0 | D25: 0
A27: CXP Impuestos | B27: ='ESFA feb 2025'!E40+'ESFA feb 2025'!E41 -> 374093 | C27: ='ESFA feb 2025'!C40+'ESFA feb 2025'!C41 -> 257751.88 | D27: ='ESFA abril 2025'!E38+'ESFA abril 2025'!E39 -> 138041.38 | E27: ='ESFA abril 2025'!C38+'ESFA abril 2025'!C39 -> 167450.88 | G27: ='ESFA MAY 2025'!C38 -> 102902.06 | I27: ='ESFA JUN 2025'!C38 -> 62996.27 | K27: ='ESFA JUL 2025'!C38 -> 274160.06 | M27: ='ESFA AGOST 2025'!C38 -> 135159.06
A29: Reclamación Seguro | B29: 7425682 | C29: 7425682 | E29: ='ESFA abril 2025'!C43 -> 0
A31: Cuotas extras 2023 | B31: 8549190 | C31: 9715856 | D31: ='ESFA abril 2025'!E44 -> 8550122 | E31: ='ESFA abril 2025'!C44 -> 0 | I31: ='ESFA JUL 2025'!E44 -> 8550122 | K31: ='ESFA JUL 2025'!C44 -> 8550122 | M31: ='ESFA AGOST 2025'!C44 -> 8550122
A33: Inversiòn vigilancia | B33: 3837291 | C33: 3837291 | D33: 3837291 | E33: 0
A35: Cuota extra 2024 | B35: ='ESFA feb 2025'!E48 -> 44870833 | C35: ='ESFA feb 2025'!C48 -> 44870833 | D35: ='ESFA abril 2025'!C46 -> 21864370 | E35: ='ESFA abril 2025'!E46 -> 44870833 | G35: ='ESFA MAY 2025'!C46 -> 45463373 | I35: ='ESFA JUL 2025'!E46 -> 44870845 | K35: ='ESFA JUL 2025'!C46 -> 44870845 | M35: ='ESFA AGOST 2025'!C46 -> 44870845
A36: Cuota extra 2025 | G36: ='ESFA MAY 2025'!C47 -> 7500003 | I36: ='ESFA JUL 2025'!E47 -> 7500003 | K36: ='ESFA JUL 2025'!C47 -> 7500003 | M36: ='ESFA AGOST 2025'!C47 -> 14999996
A37: TOTAL PASIVOS | B37: =SUM(B23:B36) -> 66086679 | C37: =SUM(C23:C36) -> 67552350 | D37: =[5]ESFA!E51 -> 29813541 | E37: =[5]ESFA!C51 -> 25473877 | G37: =[5]ESFA!E51 -> 29813541 | I37: =SUM(I23:I36) -> 61711017 | K37: ='ESFA JUL 2025'!C53 -> 61872678 | M37: ='ESFA AGOST 2025'!C48 -> 68420963
A39: PATRIMONIO
B40: Enero | C40: Febrero | D40: Marzo | E40: Abril | G40: Mayo | I40: Junio | K40: Julio | M40: Agosto
A41: Reserva de ley 675 2001 | B41: ='ESFA feb 2025'!C57 -> 8861215.9 | C41: ='ESFA feb 2025'!E57 -> 8574200.9 | D41: ='ESFA abril 2025'!E55 -> 9148230.1 | E41: ='ESFA abril 2025'!C55 -> 9476606.9 | G41: ='ESFA MAY 2025'!C56 -> 9773964.9 | I41: ='ESFA JUN 2025'!C56 -> 10053730 | K41: ='ESFA JUL 2025'!C56 -> 10351088 | M41: ='ESFA AGOST 2025'!C56 -> 10648444
A43: Resultados del presente ejercicio | B43: ='ESFA feb 2025'!C59 -> 563544.11 | C43: ='ESFA feb 2025'!E59 -> 56589.37 | D43: ='ESFA abril 2025'!E57 -> 595837.69 | E43: ='ESFA abril 2025'!C57 -> 6876070.4 | G43: ='ESFA MAY 2025'!C58 -> 7171827.1 | I43: ='ESFA JUN 2025'!C58 -> 10687867 | K43: ='ESFA JUL 2025'!C58 -> 11854266 | M43: ='ESFA AGOST 2025'!C58 -> 11808814
A45: Excedente- reconocimiento talud | B45: ='ESFA feb 2025'!E58 -> 7100905.5 | C45: ='ESFA feb 2025'!C58 -> 7100905.5 | D45: ='ESFA abril 2025'!E58 -> -49920464 | E45: ='ESFA abril 2025'!C56 -> 0 | G45: ='ESFA MAY 2025'!C59 -> 248452.74 | I45: ='ESFA JUN 2025'!C59 -> 248452.74 | K45: ='ESFA JUL 2025'!C59 -> 248451.86 | M45: ='ESFA AGOST 2025'!C59 -> 248451.86
A46: TOTAL PATRIMONIO | E46: =E41+E43+E45 -> 16352677 | G46: =G41+G43+G45 -> 17194245 | I46: =SUM(I41:I45) -> 20990049 | K46: ='ESFA JUL 2025'!C60 -> 22453806 | M46: ='ESFA AGOST 2025'!C60 -> 22705710
B47: =SUM(B41:B45) -> 16525665 | C47: =SUM(C41:C45) -> 15731696 | D47: =SUM(D41:D45) -> -40176396
E50: 45748 | G50: 45778 | I50: 45809 | K50: 45839 | M50: 45870
A51: Activo | E51: =E17 -> 45098563 | G51: =G17 -> 79344897 | I51: =I17 -> 82701066 | K51: =K17 -> 84326484 | M51: ='ESFA AGOST 2025'!C32 -> 91939380
A52: Pasivo | E52: =E37 -> 25473877 | G52: =G37 -> 29813541 | I52: =I37 -> 61711017 | K52: =K37 -> 61872678 | M52: ='ESFA AGOST 2025'!C53 -> 69233670
A53: Patrimonio | E53: =E46 -> 16352677 | G53: =G46 -> 17194245 | I53: =I46 -> 20990049 | K53: =K46 -> 22453806 | M53: ='ESFA AGOST 2025'!C60 -> 22705710
A55: IINDICADOR LIQUIDEZ | G55: 45778 | I55: 45809 | K55: 45839 | M55: 45870
A56: Activo cte | G56: =G51 -> 79344897 | I56: =I51 -> 82701066 | K56: =K51 -> 84326484 | M56: =M51 -> 91939380
A57: Pasivo cte | G57: =G52 -> 29813541 | I57: =I52 -> 61711017 | K57: =K52 -> 61872678 | M57: =M52 -> 69233670
A58: Indice de liquidez | G58: =G56/G57 -> 2.6613711 | I58: =I56/I57 -> 1.3401346 | K58: =K56/K57 -> 1.3629034 | M58: =M56/M57 -> 1.3279576
A59: Indice base | G59: 1 | I59: 1 | K59: 1 | M59: 1

Sheet ESFA JUL 2025
B2: URBANIZACION MONTEVERDI P.H. NIT 900.317.187.5
B4: ESTADO DE LA SITUACION FINANCIERA COMPARATIVO: *JUNIO 2025-JULIO 2025*
B6: ACTIVO | C6: 28/07//2025 | E6: 28/06//2025 | G6: DIF. $ | H6: DIF. %
B8: EFECTIVO Y SUS EQUIVALENTES
B9: CAJA MENOR | C9: 200000 | E9: 200000 | G9: =-C9+E9 -> 0 | H9: =+G9/C9 -> 0
B10: BANCOLOMBIA CUENTA DE OPERACIÓN | C10: =408000+50367680.84 -> 50775681 | E10: 47966179 | G10: =-C10+E10 -> -2809502.2 | H10: =+G10/C10 -> -0.05533165
C11: =SUM(C9:C10) -> 50975681 | E11: =SUM(E9:E10) -> 48166179 | G11: =SUM(G9:G10) -> -2809502.2 | H11: =+G11/C11 -> -0.05511456
B12: EFECTIVO RESTRINGIDO
B13: INVERSIONES
B14: INVERSION CDT | C14: 0 | E14: 0
B15: FIDUCUENTA BANCOLOMBIA | C15: 10852428 | E15: 10764304 | G15: =-C15+E15 -> -88124.35 | H15: =+G15/C15 -> -0.0081202428
C16: =SUM(C14:C15) -> 10852428 | E16: =SUM(E14:E15) -> 10764304 | G16: =-C16+E16 -> -88124.35 | H16: =+G16/C16 -> -0.0081202428
B18: CUENTAS POR COBRAR
B20: DEUDORES CORRIENTES
B21: COPROPIETARIOS | C21: 8689091 | E21: 11341985 | G21: =+E21-C21 -> 2652894 | H21: =+G21/C21 -> 0.30531318
B22: CONSIGNACIONES POR IDENTIFICAR | C22: -408000 | E22: 0 | G22: =+E22-C22 -> 408000 | H22: 0
C23: =SUM(C21:C22) -> 8281091 | E23: =SUM(E21:E22) -> 11341985 | G23: =SUM(G21:G22) -> 3060894 | H23: =+G23/C23 -> 0.36962449
B25: ANTICIPO PROVEEDORES | C25: 0 | E25: 0 | G25: =+E25-C25 -> 0 | H25: 0
B26: ANTICIPO OBRA TALUD-TUBERIAS | C26: 0 | E26: 0 | G26: =+E26-C26 -> 0
B27: DEUDORES VARIOS | C27: 3232000 | E27: 0
G28: =+E28-C28 -> 0
B29: GASTOS PAGADOS POR ANTICIPADO
B30: POLIZA SEGURO | C30: 10985284 | E30: 12428599 | G30: =+E30-C30 -> 1443315 | H30: =+G30/C30 -> 0.13138623
B32: TOTAL ACTIVO | C32: =+C11+C16+C23+C25+C30+C26+C27 -> 84326484 | E32: =+E11+E16+E23+E25+E30+E26+E27 -> 82701066 | G32: =-C32+E32 -> -1625417.6 | H32: =+G32/C32 -> -0.019275291
B34: PASIVO
B36: CUENTAS POR PAGAR
B37: COSTOS Y GASTOS POR PAGAR | C37: =-142800+820348 -> 677548 | E37: 727051 | G37: =+E37-C37 -> 49503 | H37: =+G37/C37 -> 0.073061982
B38: RETENCION IMPUESTOS | C38: 274160.06 | E38: =0.21+62996.06 -> 62996.27 | G38: =-C38+E38 -> -211163.79 | H38: =+G38/C38 -> -0.77022083
B39: RETEICA | C39: 0 | E39: 0
C40: =SUM(C37:C39) -> 951708.06 | E40: =SUM(E37:E39) -> 790047.27 | G40: =SUM(G37:G38) -> -161660.79 | H40: =+G40/C40 -> -0.16986384
B41: PASIVOS DIFERIDOS
B42: INGRESOS RECIBIDOS DE TERCEROS | J42: DECISIONES ASAMBLEA
B43: CUOTA EXTRA 2022-RECONOCIMIENTO SEGURO | C43: 0 | E43: 0 | J43: GASTOS NO PRESUPUESTADOS X DEFINIR TALUD | K43: =-49920464 -> -49920464 | M43: 31805050
B44: CUOTA EXTRA 2023 | C44: 8550122 | E44: 8550122 | G44: =-C44+E44 -> 0 | H44: NA | J44: DEFICIT PPTAL 2023 | K44: -893269.33 | M44: -248452.74
B45: REINVERSIÓN 2023 | C45: 0 | E45: 0 | G45: =-C45+E45 -> 0 | H45: NA | J45: TOTAL A CUBRIR | K45: =SUM(K43:K44) -> -50813733 | M45: -8550122
B46: CUOTA EXTRA 2024 | C46: 44870845 | E46: 44870845 | G46: =-C46+E46 -> 0 | J46: CUBRIR ASI SEGÚN DECISIÓN ASAMBLEA | M46: =SUM(M43:M45) -> 23006475 | N46: =+M46+E46 -> 67877320
B47: CUOTA EXTRA 2025 | C47: 7500003 | E47: 7500003 | G47: =-C47+E47 -> 0 | J47: CUOTA EXTRA 2022-RECONOCIMIENTO SEGURO | K47: 7425682
B48: TOTAL PASIVOS DIFERIDOS | C48: =SUM(C43:C47) -> 60920970 | E48: =SUM(E43:E47) -> 60920970 | G48: =SUM(G44:G45) -> 0 | H48: =+G48/C48 -> 0 | J48: CUOTA EXTRA 2023 | K48: 8550122
J49: REINVERSIÓN 2023 | K49: 3837291
B50: OTROS PASIVOS | J50: CUOTA EXTRA 2024 | K50: 23006464
...

Sheet ESFA JUN 2025
B2: URBANIZACION MONTEVERDI P.H. NIT 900.317.187.5
B4: ESTADO DE LA SITUACION FINANCIERA COMPARATIVO: *MAYO 2025-JUNIO 2025*
B6: ACTIVO | C6: 28/06//2025 | E6: 28/05//2025 | G6: DIF. $ | H6: DIF. %
B8: EFECTIVO Y SUS EQUIVALENTES
B9: CAJA MENOR | C9: 200000 | E9: 200000 | G9: =-C9+E9 -> 0 | H9: =+G9/C9 -> 0
B10: BANCOLOMBIA CUENTA DE OPERACIÓN | C10: 47966179 | E10: 52672061 | G10: =-C10+E10 -> 4705882.1 | H10: =+G10/C10 -> 0.098108339
C11: =SUM(C9:C10) -> 48166179 | E11: =SUM(E9:E10) -> 52872061 | G11: =SUM(G9:G10) -> 4705882.1 | H11: =+G11/C11 -> 0.097700965
B12: EFECTIVO RESTRINGIDO
B13: INVERSIONES
B14: INVERSION CDT | C14: 0 | E14: 0
B15: FIDUCUENTA BANCOLOMBIA | C15: 10764304 | E15: 8658779.9 | G15: =-C15+E15 -> -2105523.7 | H15: =+G15/C15 -> -0.19560241
C16: =SUM(C14:C15) -> 10764304 | E16: =SUM(E14:E15) -> 8658779.9 | G16: =-C16+E16 -> -2105523.7 | H16: =+G16/C16 -> -0.19560241
B18: CUENTAS POR COBRAR
B20: DEUDORES CORRIENTES
B21: COPROPIETARIOS | C21: 11341985 | E21: 3942142 | G21: =+E21-C21 -> -7399843 | H21: =+G21/C21 -> -0.65242927
B22: CONSIGNACIONES POR IDENTIFICAR | C22: 0 | E22: 0 | G22: =+E22-C22 -> 0 | H22: 0
C23: =SUM(C21:C22) -> 11341985 | E23: =SUM(E21:E22) -> 3942142 | G23: =SUM(G21:G22) -> -7399843 | H23: =+G23/C23 -> -0.65242927
B25: ANTICIPO PROVEEDORES | C25: 0 | E25: 0 | G25: =+E25-C25 -> 0 | H25: 0
B26: ANTICIPO OBRA TALUD-TUBERIAS | C26: 0 | E26: 0 | G26: =+E26-C26 -> 0
B27: DEUDORES VARIOS | C27: 0 | E27: 0
G28: =+E28-C28 -> 0
B29: GASTOS PAGADOS POR ANTICIPADO
B30: POLIZA SEGURO | C30: 12428599 | E30: 13871914 | G30: =+E30-C30 -> 1443315 | H30: =+G30/C30 -> 0.11612854
B32: TOTAL ACTIVO | C32: =+C11+C16+C23+C25+C30+C26+C27 -> 82701066 | E32: =+E11+E16+E23+E25+E30+E26+E27 -> 79344897 | G32: =-C32+E32 -> -3356169.6 | H32: =+G32/C32 -> -0.040581938
B34: PASIVO
B36: CUENTAS POR PAGAR
B37: COSTOS Y GASTOS POR PAGAR | C37: 727051 | E37: 534252 | G37: =+E37-C37 -> -192799 | H37: =+G37/C37 -> -0.26517947
B38: RETENCION IMPUESTOS | C38: =0.21+62996.06 -> 62996.27 | E38: =-0.09+102902.06 -> 102901.97 | G38: =-C38+E38 -> 39905.7 | H38: =+G38/C38 -> 0.63346131
B39: RETEICA | C39: 0 | E39: 0
C40: =SUM(C37:C39) -> 790047.27 | E40: =SUM(E37:E39) -> 637153.97 | G40: =SUM(G37:G38) -> -152893.3 | H40: =+G40/C40 -> -0.19352424
B41: PASIVOS DIFERIDOS
B42: INGRESOS RECIBIDOS DE TERCEROS | J42: DECISIONES ASAMBLEA
B43: CUOTA EXTRA 2022-RECONOCIMIENTO SEGURO | C43: 0 | E43: 0 | J43: GASTOS NO PRESUPUESTADOS X DEFINIR TALUD | K43: =-49920464 -> -49920464 | M43: 31805050
B44: CUOTA EXTRA 2023 | C44: 8550122 | E44: 8550122 | G44: =-C44+E44 -> 0 | H44: NA | J44: DEFICIT PPTAL 2023 | K44: -893269.33 | M44: -248452.74
B45: REINVERSIÓN 2023 | C45: 0 | E45: 0 | G45: =-C45+E45 -> 0 | H45: NA | J45: TOTAL A CUBRIR | K45: =SUM(K43:K44) -> -50813733 | M45: -8550122
B46: CUOTA EXTRA 2024 | C46: 44870845 | E46: 45463373 | G46: =-C46+E46 -> 592528.12 | J46: CUBRIR ASI SEGÚN DECISIÓN ASAMBLEA | M46: =SUM(M43:M45) -> 23006475 | N46: =+M46+E46 -> 68469848
B47: CUOTA EXTRA 2025 | C47: 7500003 | E47: 7500003 | G47: =-C47+E47 -> 0 | J47: CUOTA EXTRA 2022-RECONOCIMIENTO SEGURO | K47: 7425682
B48: TOTAL PASIVOS DIFERIDOS | C48: =SUM(C43:C47) -> 60920970 | E48: =SUM(E43:E47) -> 61513498 | G48: =SUM(G44:G45) -> 0 | H48: =+G48/C48 -> 0 | J48: CUOTA EXTRA 2023 | K48: 8550122
J49: REINVERSIÓN 2023 | K49: 3837291
B50: OTROS PASIVOS | J50: CUOTA EXTRA 2024 | K50: 23006464
...

Sheet ESFA JUN GRAF 2025
A1: CR URBANIZACION MONTEVERDI P.H. - 900.317.187-5
A2: ESTADO DE SITUACION FINANCIERA AÑO 2025
A3: ACTIVOS
B4: Enero | C4: Febrero | D4: Marzo | E4: Abril | G4: Mayo | I4: Junio | K4: Julio | L4: Agosto
A5: Efectivo y sus equivalentes | B5: ='ESFA feb 2025'!E11 -> 19036449 | C5: ='ESFA feb 2025'!C11 -> 18027328 | D5: ='ESFA abril 2025'!E11 -> 16632366 | E5: ='ESFA abril 2025'!C11 -> 16436254 | G5: ='ESFA MAY 2025'!C11 -> 52872061 | I5: ='ESFA JUN 2025'!C11 -> 48166179
A7: Fiducuenta Bancolombia | B7: ='ESFA feb 2025'!E16 -> 8425444.3 | C7: ='ESFA feb 2025'!C17 -> 8477538.3 | D7: ='ESFA abril 2025'!E16 -> 8534559.7 | E7: ='ESFA abril 2025'!C15 -> 8594287.8 | G7: ='ESFA MAY 2025'!C15 -> 8658779.9 | I7: ='ESFA JUN 2025'!C15 -> 10764304
A9: CXC Administración | B9: ='ESFA feb 2025'!E22 -> 4645234 | C9: ='ESFA feb 2025'!C22 -> 5984340 | D9: ='ESFA abril 2025'!E23 -> 4129452 | E9: ='ESFA abril 2025'!C21 -> 4269712 | G9: ='ESFA MAY 2025'!C21 -> 3942142 | I9: ='ESFA JUN 2025'!C21 -> 11341985
A11: Pagos sin identificar | B11: -503652 | C11: =[4]ESFA!E22 -> -503652 | D11: 0 | E11: 0
A13: Reclamaciones a proveedores | B13: ='ESFA feb 2025'!E28 -> 33310 | C13: ='ESFA feb 2025'!C28 -> 50146 | D13: ='ESFA abril 2025'!E27 -> 38070 | E13: ='ESFA abril 2025'!C27 -> 440118 | G13: ='ESFA MAY 2025'!C27 -> 0
A15: Gasto por anticipado póliza seguros | B15: ='ESFA feb 2025'!E31 -> 1357394 | C15: ='ESFA feb 2025'!C31 -> 452464 | D15: ='ESFA abril 2025'!E30 -> 16844468 | E15: ='ESFA abril 2025'!C30 -> 15358191 | G15: ='ESFA MAY 2025'!C30 -> 13871914 | I15: ='ESFA JUN 2025'!C30 -> 12428599
E16: =SUM(E5:E16) -> 0
A17: TOTAL ACTIVO | B17: =SUM(B5:B15) -> 32994180 | C17: =SUM(C5:C16) -> 32488164 | D17: =SUM(D5:D16) -> 46178916 | E17: =E5+E7+E9+E13+E15 -> 45098563 | G17: =G5+G7+G9+G13+G15 -> 79344897 | I17: ='ESFA JUN 2025'!C32 -> 82701066 | L17: =++L5+L7+L9+L11 -> 0
A21: PASIVOS
B22: Enero | C22: Febrero | D22: Marzo | E22: Abril | G22: Mayo | I22: Junio | K22: Julio | L22: Agosto
A23: CXP honorarios | B23: ='ESFA feb 2025'!E39 -> 1029590 | C23: ='ESFA feb 2025'!C39 -> 1444936 | D23: ='ESFA abril 2025'!E37 -> 14432437 | E23: ='ESFA abril 2025'!C37 -> 6714065 | G23: ='ESFA MAY 2025'!C37 -> 534252 | I23: ='ESFA JUN 2025'!C37 -> 727051
A25: CXP | C25: 0 | D25: 0
A27: CXP Impuestos | B27: ='ESFA feb 2025'!E40+'ESFA feb 2025'!E41 -> 374093 | C27: ='ESFA feb 2025'!C40+'ESFA feb 2025'!C41 -> 257751.88 | D27: ='ESFA abril 2025'!E38+'ESFA abril 2025'!E39 -> 138041.38 | E27: ='ESFA abril 2025'!C38+'ESFA abril 2025'!C39 -> 167450.88 | G27: ='ESFA MAY 2025'!C38 -> 102902.06 | I27: ='ESFA JUN 2025'!C38 -> 62996.27
A29: Reclamación Seguro | B29: 7425682 | C29: 7425682 | E29: ='ESFA abril 2025'!C43 -> 0
A31: Cuotas extras 2023 | B31: 8549190 | C31: 9715856 | D31: ='ESFA abril 2025'!E44 -> 8550122 | E31: ='ESFA abril 2025'!C44 -> 0
A33: Saldo Inversión vigilancia | B33: 3837291 | C33: 3837291 | D33: 3837291 | E33: 0
A35: Cuota extra 2024 | B35: ='ESFA feb 2025'!E48 -> 44870833 | C35: ='ESFA feb 2025'!C48 -> 44870833 | D35: ='ESFA abril 2025'!C46 -> 21864370 | E35: ='ESFA abril 2025'!E46 -> 44870833 | G35: ='ESFA MAY 2025'!C46 -> 45463373 | I35: ='ESFA JUN 2025'!C46 -> 44870845
A36: Cuota extra 2025 | G36: ='ESFA MAY 2025'!C47 -> 7500003 | I36: ='ESFA JUN 2025'!C47 -> 7500003
B37: =SUM(B23:B36) -> 66086679 | C37: =SUM(C23:C36) -> 67552350 | D37: =[5]ESFA!E51 -> 29813541 | E37: =[5]ESFA!C51 -> 25473877 | G37: =[5]ESFA!E51 -> 29813541 | I37: =SUM(I23:I36) -> 53160895
A39: PATRIMONIO
B40: Enero | C40: Febrero | D40: Marzo | E40: Abril | G40: Mayo | I40: Junio | K40: Julio | L40: Agosto
A41: Reserva de ley 675 2001 | B41: ='ESFA feb 2025'!C57 -> 8861215.9 | C41: ='ESFA feb 2025'!E57 -> 8574200.9 | D41: ='ESFA abril 2025'!E55 -> 9148230.1 | E41: ='ESFA abril 2025'!C55 -> 9476606.9 | G41: ='ESFA MAY 2025'!C56 -> 9773964.9 | I41: ='ESFA JUN 2025'!C56 -> 10053730
A43: Resultados del presente ejercicio | B43: ='ESFA feb 2025'!C59 -> 563544.11 | C43: ='ESFA feb 2025'!E59 -> 56589.37 | D43: ='ESFA abril 2025'!E57 -> 595837.69 | E43: ='ESFA abril 2025'!C57 -> 6876070.4 | G43: ='ESFA MAY 2025'!C58 -> 7171827.1 | I43: ='ESFA JUN 2025'!C58 -> 10687867
A45: Excedente- reconocimiento talud | B45: ='ESFA feb 2025'!E58 -> 7100905.5 | C45: ='ESFA feb 2025'!C58 -> 7100905.5 | D45: ='ESFA abril 2025'!E58 -> -49920464 | E45: ='ESFA abril 2025'!C56 -> 0 | G45: ='ESFA MAY 2025'!C59 -> 248452.74 | I45: ='ESFA JUN 2025'!C59 -> 248452.74
E46: =E41+E43+E45 -> 16352677 | G46: =G41+G43+G45 -> 17194245 | I46: =SUM(I41:I45) -> 20990049
B47: =SUM(B41:B45) -> 16525665 | C47: =SUM(C41:C45) -> 15731696 | D47: =SUM(D41:D45) -> -40176396
E50: 45748 | G50: 45778 | I50: 45809
A51: ACTIVO | E51: =E17 -> 45098563 | G51: =G17 -> 79344897 | I51: =I17 -> 82701066
A52: PASIVO | E52: =E37 -> 25473877 | G52: =G37 -> 29813541 | I52: =I37 -> 53160895
A53: PATRIMONIO | E53: =E46 -> 16352677 | G53: =G46 -> 17194245 | I53: =I46 -> 20990049

Sheet ESTAD RESUL JUN
B1: URBANIZACION MONTEVERDI P.H. NIT 900.317.187.5
B3: ESTADO INTEGRAL DE RESULTADOS A 31 DEJUNIO DE 2025
A5: 1 | B5: 6 | C5: PPTO ANUAL2025 | D5: PTTO.2025 | E5: REAL ENE. | F5: REAL FEB | G5: REAL MARZO | H5: REAL ABR | I5: REAL MAY | J5: REAL JUN | K5: REAL JUL | L5: REAL AGO | M5: REAL SEP | N5: REAL OCT | O5: REAL NOV | P5: REAL DIC | Q5: EJECUTADO ACUMUL. | R5: PTTO. ACUMUL. | S5: SOBRE O SUBEJECUCION | T5: VARIACION
B6: CUOTAS DE ADMINISTRACION | C6: 353308839 | D6: =+C6/12 -> 29442403 | E6: =-287015+28701567 -> 28414552 | F6: 28414552 | G6: 28414552 | H6: =+H8-H7 -> 32509259 | I6: =29735584-I7 -> 29438226 | J6: =+J8-J7 -> 29438226 | Q6: =SUM(E6:P6) -> 176629367 | R6: =+D6*$B$5 -> 1.7665442e+08 | S6: =+R6-Q6 -> 25052.5 | T6: =+R6-Q6 -> 25052.5
B7: Ing x Fondo imprevistos | C7: 3533088 | D7: =+C7/12 -> 294424 | E7: 287015 | F7: 287015 | G7: 287015 | H7: 328376 | I7: 297358 | J7: 297358 | Q7: =SUM(E7:P7) -> 1784137 | R7: =+D7*$B$5 -> 1766544 | S7: =+R7-Q7 -> -17593 | T7: =+R7-Q7 -> -17593
B8: TOTAL INGRESO OPERACIONAL | C8: =+C6+C7 -> 356841927 | D8: =SUM(D6:D7) -> 29736827 | E8: =SUM(E6:E7) -> 28701567 | F8: =SUM(F6:F7) -> 28701567 | G8: =SUM(G6:G7) -> 28701567 | H8: 32837635 | I8: =+I6+I7 -> 29735584 | J8: 29735584 | K8: =SUM(K6:K7) -> 0 | L8: 27282827 | M8: =SUM(M6:M7) -> 0 | N8: =SUM(N6:N7) -> 0 | O8: =SUM(O6:O7) -> 0 | P8: =SUM(P6:P7) -> 0 | Q8: =SUM(Q6:Q7) -> 178413504 | R8: =+D8*$B$5 -> 1.7842096e+08 | S8: =+R8-Q8 -> 7459.5 | T8: =+R8-Q8 -> 7459.5
B9: Gastos Operacionales
B10: Mantenimiento (Infraestructura)
B11: Aseo Y Piscina (Personal) | C11: 33199438 | D11: =+C11/12 -> 2766619.9 | E11: 2766619 | F11: 2766619 | G11: 2766619 | H11: 2766619 | I11: 2827988 | J11: 2766620 | Q11: =SUM(E11:P11) -> 16661084 | R11: =+D11*$B$5 -> 16599719 | S11: =+R11-Q11 -> -61364.84 | T11: =+R11-Q11 -> -61364.84
B12: Aseo (Insumos) | C12: 1260000 | D12: =+C12/12 -> 105000 | E12: 143550 | F12: 235199 | G12: 220474 | H12: 175110 | I12: 120400 | J12: 95350 | Q12: =SUM(E12:P12) -> 990083 | R12: =+D12*$B$5 -> 630000 | S12: =+R12-Q12 -> -360083 | T12: =+R12-Q12 -> -360083
B13: Zonas Comunes General | C13: 10500000 | D13: =+C13/12 -> 875000 | E13: 1581421 | F13: 0 | G13: =196100+277737+50000 -> 523837 | H13: 338825 | I13: =-111750+278850 -> 167100 | J13: 1050763 | Q13: =SUM(E13:P13) -> 3661946 | R13: =+D13*$B$5 -> 5250000 | S13: =+R13-Q13 -> 1588054 | T13: =+R13-Q13 -> 1588054
B14: Mantenimento Electrico | C14: 1800000 | D14: =+C14/12 -> 150000 | E14: 229300 | F14: 104000 | G14: 366738 | I14: 6000 | J14: 122000 | Q14: =SUM(E14:P14) -> 828038 | R14: =+D14*$B$5 -> 900000 | S14: =+R14-Q14 -> 71962 | T14: =+R14-Q14 -> 71962
B15: Piscina-Zona Húmeda-Turco | C15: 11900000 | D15: =+C15/12 -> 991666.67 | E15: 823302 | F15: 1301779 | G15: 611281 | H15: 203409 | I15: 984464 | J15: 203409 | Q15: =SUM(E15:P15) -> 4127644 | R15: =+D15*$B$5 -> 5950000 | S15: =+R15-Q15 -> 1822356 | T15: =+R15-Q15 -> 1822356
B16: Puerta Vehicular Y Peatonal | C16: 590000 | D16: =+C16/12 -> 49166.667 | E16: 0 | F16: 140000 | G16: 0 | Q16: =SUM(E16:P16) -> 140000 | R16: =+D16*$B$5 -> 295000 | S16: =+R16-Q16 -> 155000 | T16: =+R16-Q16 -> 155000
B17: Gimnasio | C17: 2429980 | D17: =+C17/12 -> 202498.33 | E17: 246330 | F17: 0 | G17: 749700 | I17: 246330 | J17: 0 | Q17: =SUM(E17:P17) -> 1242360 | R17: =+D17*$B$5 -> 1214990 | S17: =+R17-Q17 -> -27370 | T17: =+R17-Q17 -> -27370
B18: Dotacion | C18: 0 | D18: =+C18/12 -> 0 | E18: 0 | F18: 350000 | Q18: =SUM(E18:P18) -> 350000 | R18: =+D18*$B$5 -> 0 | S18: =+R18-Q18 -> -350000 | T18: =+R18-Q18 -> -350000
B19: Total Mantenimiento Y Mejoras | C19: =SUM(C11:C18) -> 61679418 | D19: =SUM(D11:D18) -> 5139951.5 | E19: =SUM(E11:E18) -> 5790522 | F19: =SUM(F11:F18) -> 4897597 | G19: =SUM(G11:G18) -> 5238649 | H19: =SUM(H11:H18) -> 3483963 | I19: =SUM(I11:I18) -> 4352282 | J19: =SUM(J11:J17) -> 4238142 | K19: =SUM(K11:K17) -> 0 | L19: =SUM(L11:L17) -> 0 | M19: =SUM(M11:M17) -> 0 | N19: =SUM(N11:N17) -> 0 | O19: =SUM(O11:O17) -> 0 | P19: =SUM(P11:P17) -> 0 | Q19: =SUM(Q11:Q18) -> 28001155 | R19: =+D19*$B$5 -> 30839709 | S19: =SUM(S11:S17) -> 3188554.2 | T19: =+R19-Q19 -> 2838554.2
B20: Seguridad | D20: =+C20/12 -> 0
B21: Vigilancia Privada | C21: 1.5883039e+08 | D21: =+C21/12 -> 13235866 | E21: 13136493 | F21: 13136493 | G21: 13136494 | H21: 13136494 | I21: 13136494 | J21: 13136493 | Q21: =SUM(E21:P21) -> 78818961 | R21: =+D21*$B$5 -> 79415196 | S21: =+R21-Q21 -> 596235.08 | T21: =+R21-Q21 -> 596235.08
B22: Refuerzo Vigilancia | C22: =1751531+2225540 -> 3977071 | D22: =+C22/12 -> 331422.58 | F22: 1751531 | Q22: =SUM(E22:P22) -> 1751531 | R22: =+D22*$B$5 -> 1988535.5 | T22: =+R22-Q22 -> 237004.5
B23: Seguro Zonas Comunes | C23: 17577558 | D23: =+C23/12 -> 1464796.5 | E23: 1357394 | F23: 904930 | G23: 1443315 | H23: 1486277 | I23: 1486277 | J23: 1443315 | Q23: =SUM(E23:P23) -> 8121508 | R23: =+D23*$B$5 -> 8788779 | S23: =+R23-Q23 -> 667271 | T23: =+R23-Q23 -> 667271
B24: Sistema De Seguridad Prev | C24: 1341006.2 | D24: =+C24/12 -> 111750.52 | E24: 640110 | F24: 111750 | G24: 111750 | H24: 111750 | I24: 111750 | J24: 111750 | Q24: =SUM(E24:P24) -> 1198860 | R24: =+D24*$B$5 -> 670503.12 | S24: =+R24-Q24 -> -528356.88 | T24: =+R24-Q24 -> -528356.88
B25: Sistema De Seg.Repuestos | C25: 1950000 | D25: =+C25/12 -> 162500 | E25: 0 | F25: 0 | G25: 0 | I25: 555730 | J25: 142800 | Q25: =SUM(E25:P25) -> 698530 | R25: =+D25*$B$5 -> 975000 | T25: =+R25-Q25 -> 276470
B26: Sg-Sst, Requisto De Ley | C26: 1910000 | D26: =+C26/12 -> 159166.67 | E26: 0 | F26: 0 | G26: 288000 | H26: 50000 | I26: 305387 | Q26: =SUM(E26:P26) -> 643387 | R26: =+D26*$B$5 -> 955000 | S26: =+R26-Q26 -> 311613 | T26: =+R26-Q26 -> 311613
B27: Extintores (Recarga) | C27: 372000 | D27: =+C27/12 -> 31000 | E27: 0 | F27: 0 | G27: 0 | Q27: =SUM(E27:P27) -> 0 | R27: =+D27*$B$5 -> 186000 | S27: =+#REF!-#REF! -> #REF! | T27: =+R27-Q27 -> 186000
B28: Planes De Ley Emerg, Trat Datos | C28: 740000 | D28: =+C28/12 -> 61666.667 | F28: 138500 | G28: 0 | Q28: =SUM(E28:P28) -> 138500 | R28: =+D28*$B$5 -> 370000 | S28: =+R28-Q28 -> 231500 | T28: =+R28-Q28 -> 231500
B29: Reserva Estatutaria 1% Del Ppto (De Ley) | C29: 3533088 | D29: =+C29/12 -> 294424 | E29: =+E7 -> 287015 | F29: 287015 | G29: 287015 | H29: 328376 | I29: =-14659+297358 -> 282699 | J29: =11725+282699 -> 294424 | Q29: =SUM(E29:P29) -> 1766544 | R29: =+D29*$B$5 -> 1766544 | S29: =+R29-Q29 -> 0 | T29: =+R29-Q29 -> 0
B30: Total Riesgos Y Seguridad | C30: =SUM(C21:C29) -> 1.9023112e+08 | D30: =+C30/12 -> 15852593 | E30: =SUM(E21:E29) -> 15421012 | F30: =SUM(F21:F29) -> 16330219 | G30: =SUM(G21:G29) -> 15266574 | H30: =SUM(H21:H29) -> 15112897 | I30: =SUM(I21:I29) -> 15878337 | J30: =SUM(J21:J29) -> 15128782 | K30: =SUM(K21:K29) -> 0 | L30: =SUM(L21:L29) -> 0 | ... Q30: =SUM(Q21:Q29) -> 93137821 | R30: =+D30*$B$5 -> 95115558 | S30: =SUM(S21:S29) -> #REF! | T30: =+R30-Q30 -> 1977736.7
B31: Convivencia | D31: =+C31/12 -> 0
B32: Celebraciones -Navidad | C32: 0 | D32: =+C32/12 -> 0 | E32: =+D32/12 -> 0 | F32: 0 | G32: 0 | H32: 0 | I32: 0 | J32: 179214 | K32: 0 | Q32: =SUM(E32:P32) -> 179214 | R32: =+D32*$B$5 -> 0 | S32: =+R32-Q32 -> -179214 | T32: =+R32-Q32 -> -179214
B33: Asamblea (Ley) | C33: 0 | D33: =+C33/12 -> 0 | E33: =+D33/12 -> 0 | F33: 0 | G33: =46000+17700+274950 -> 338650 | H33: 0 | I33: 176715 | J33: 0 | K33: 0 | L33: 0 | M33: 0 | N33: 0 | O33: 0 | P33: 0 | Q33: =SUM(E33:P33) -> 515365 | R33: =+D33*$B$5 -> 0 | S33: =+R33-Q33 -> -515365 | T33: =+R33-Q33 -> -515365
B34: Total Convivencia | C34: =SUM(C32:C33) -> 0 | D34: =+C34/12 -> 0 | E34: =SUM(E32:E33) -> 0 | F34: =SUM(F32:F33) -> 0 | G34: =SUM(G32:G33) -> 338650 | H34: =SUM(H32:H33) -> 0 | I34: =SUM(I32:I33) -> 176715 | J34: =SUM(J32:J33) -> 179214 | K34: =SUM(K32:K33) -> 0 | L34: =SUM(L32:L33) -> 0 | ... P34: =SUM(P32:P33) -> 0 | Q34: =SUM(E34:P34) -> 694579 | R34: =SUM(R32:R33) -> 0 | S34: =SUM(S32:S33) -> -694579 | T34: =+R34-Q34 -> -694579
B35: Ambiental | D35: =+C35/12 -> 0
B36: Fumigación | C36: 2568001.5 | D36: =+C36/12 -> 214000.12 | E36: 0 | F36: 0 | G36: 595450 | H36: 0 | I36: 781652 | Q36: =SUM(E36:P36) -> 1377102 | R36: =+D36*$B$5 -> 1284000.8 | S36: =+R36-Q36 -> -93101.25 | T36: =+R36-Q36 -> -93101.25
B37: Energía | C37: =33250000*1.15 -> 38237500 | D37: =+C37/12 -> 3186458.3 | E37: 3189683.9 | F37: 2628727 | G37: 2554892 | H37: 2640861 | I37: 3098024 | J37: 2908845 | Q37: =SUM(E37:P37) -> 17021033 | R37: =+D37*$B$5 -> 19118750 | S37: =+R37-Q37 -> 2097717.1 | T37: =+R37-Q37 -> 2097717.1
B38: Acueducto Y Alcantarillado | C38: 3500000 | D38: =+C38/12 -> 291666.67 | E38: 129706 | F38: 233099 | G38: 303870 | H38: 205744 | I38: 217588 | J38: 249565 | Q38: =SUM(E38:P38) -> 1339572 | R38: =+D38*$B$5 -> 1750000 | S38: =+R38-Q38 -> 410428 | T38: =+R38-Q38 -> 410428
B39: Tasa De Aseo | C39: 604000 | D39: =+C39/12 -> 50333.333 | E39: 50100 | F39: 50115 | G39: 56102 | H39: 56070 | I39: 56076 | J39: 55806 | Q39: =SUM(E39:P39) -> 324269 | R39: =+D39*$B$5 -> 302000 | S39: =+R39-Q39 -> -22269 | T39: =+R39-Q39 -> -22269
B40: SGIRS Pemirs Ley | C40: =100988*12 -> 1211856 | D40: =+C40/12 -> 100988 | E40: 0 | F40: 0 | G40: 55250 | H40: 0 | I40: 0 | Q40: =SUM(E40:P40) -> 55250 | R40: =+D40*$B$5 -> 605928 | T40: =+R40-Q40 -> 550678
B41: Telefonía E Internet | C41: 800000 | D41: =+C41/12 -> 66666.667 | E41: 87582 | F41: 100988 | G41: 100988 | H41: 100988 | I41: 100988 | J41: 100988 | Q41: =SUM(E41:P41) -> 592522 | R41: =+D41*$B$5 -> 400000 | S41: =+R41-Q41 -> -192522 | T41: =+R41-Q41 -> -192522
B42: Corte Cesped Y Mto Jardines Z. Comun | C42: =(1187000+167200)*12 -> 16250400 | D42: =+C42/12 -> 1354200 | E42: 1354200 | F42: 1354200 | G42: 1354200 | H42: 1354200 | I42: 1354200 | Q42: =SUM(E42:P42) -> 6771000 | R42: =+D42*$B$5 -> 8125200 | S42: =+R42-Q42 -> 1354200 | T42: =+R42-Q42 -> 1354200
...

Sheet ESFA GRAF 2025
A1: CR URBANIZACION MONTEVERDI P.H. - 900.317.187-5
A2: ESTADO DE SITUACION FINANCIERA AÑO 2025
A3: ACTIVOS
B4: Enero | C4: Febrero | D4: Marzo | E4: Abril | G4: Mayo | I4: Junio | K4: Julio | L4: Agosto
A5: Efectivo y sus equivalentes | B5: ='ESFA feb 2025'!E11 -> 19036449 | C5: ='ESFA feb 2025'!C11 -> 18027328 | D5: ='ESFA abril 2025'!E11 -> 16632366 | E5: ='ESFA abril 2025'!C11 -> 16436254 | G5: ='ESFA MAY 2025'!C11 -> 52872061 | I5: ='ESFA JUN 2025'!C11 -> 48166179
A7: Fiducuenta Bancolombia | B7: ='ESFA feb 2025'!E16 -> 8425444.3 | C7: ='ESFA feb 2025'!C17 -> 8477538.3 | D7: ='ESFA abril 2025'!E16 -> 8534559.7 | E7: ='ESFA abril 2025'!C15 -> 8594287.8 | G7: ='ESFA MAY 2025'!C15 -> 8658779.9 | I7: ='ESFA JUN 2025'!C15 -> 10764304
A9: CXC Administración | B9: ='ESFA feb 2025'!E22 -> 4645234 | C9: ='ESFA feb 2025'!C22 -> 5984340 | D9: ='ESFA abril 2025'!E23 -> 4129452 | E9: ='ESFA abril 2025'!C21 -> 4269712 | G9: ='ESFA MAY 2025'!C21 -> 3942142 | I9: ='ESFA JUN 2025'!C21 -> 11341985
A11: Pagos sin identificar | B11: -503652 | C11: =[4]ESFA!E22 -> -503652 | D11: 0 | E11: 0
A13: Reclamaciones a proveedores | B13: ='ESFA feb 2025'!E28 -> 33310 | C13: ='ESFA feb 2025'!C28 -> 50146 | D13: ='ESFA abril 2025'!E27 -> 38070 | E13: ='ESFA abril 2025'!C27 -> 440118 | G13: ='ESFA MAY 2025'!C27 -> 0
A15: Gasto por anticipado póliza seguros | B15: ='ESFA feb 2025'!E31 -> 1357394 | C15: ='ESFA feb 2025'!C31 -> 452464 | D15: ='ESFA abril 2025'!E30 -> 16844468 | E15: ='ESFA abril 2025'!C30 -> 15358191 | G15: ='ESFA MAY 2025'!C30 -> 13871914 | I15: ='ESFA JUN 2025'!C30 -> 12428599
E16: =SUM(E5:E16) -> 0
A17: TOTAL ACTIVO | B17: =SUM(B5:B15) -> 32994180 | C17: =SUM(C5:C16) -> 32488164 | D17: =SUM(D5:D16) -> 46178916 | E17: =E5+E7+E9+E13+E15 -> 45098563 | G17: =G5+G7+G9+G13+G15 -> 79344897 | I17: ='ESFA JUN 2025'!C32 -> 82701066 | L17: =++L5+L7+L9+L11 -> 0
A21: PASIVOS
B22: Enero | C22: Febrero | D22: Marzo | E22: Abril | G22: Mayo | I22: Junio | K22: Julio | L22: Agosto
A23: CXP honorarios | B23: ='ESFA feb 2025'!E39 -> 1029590 | C23: ='ESFA feb 2025'!C39 -> 1444936 | D23: ='ESFA abril 2025'!E37 -> 14432437 | E23: ='ESFA abril 2025'!C37 -> 6714065 | G23: ='ESFA MAY 2025'!C37 -> 534252 | I23: ='ESFA JUN 2025'!C37 -> 727051
A25: CXP | C25: 0 | D25: 0
A27: CXP Impuestos | B27: ='ESFA feb 2025'!E40+'ESFA feb 2025'!E41 -> 374093 | C27: ='ESFA feb 2025'!C40+'ESFA feb 2025'!C41 -> 257751.88 | D27: ='ESFA abril 2025'!E38+'ESFA abril 2025'!E39 -> 138041.38 | E27: ='ESFA abril 2025'!C38+'ESFA abril 2025'!C39 -> 167450.88 | G27: ='ESFA MAY 2025'!C38 -> 102902.06 | I27: ='ESFA JUN 2025'!C38 -> 62996.27
A29: Reclamación Seguro | B29: 7425682 | C29: 7425682 | E29: ='ESFA abril 2025'!C43 -> 0
A31: Cuotas extras 2023 | B31: 8549190 | C31: 9715856 | D31: ='ESFA abril 2025'!E44 -> 8550122 | E31: ='ESFA abril 2025'!C44 -> 0
A33: Saldo Inversión vigilancia | B33: 3837291 | C33: 3837291 | D33: 3837291 | E33: 0
A35: Cuota extra 2024 | B35: ='ESFA feb 2025'!E48 -> 44870833 | C35: ='ESFA feb 2025'!C48 -> 44870833 | D35: ='ESFA abril 2025'!C46 -> 21864370 | E35: ='ESFA abril 2025'!E46 -> 44870833 | G35: ='ESFA MAY 2025'!C46 -> 45463373 | I35: ='ESFA JUN 2025'!C46 -> 44870845
A36: Cuota extra 2025 | G36: ='ESFA MAY 2025'!C47 -> 7500003 | I36: ='ESFA JUN 2025'!C47 -> 7500003
B37: =SUM(B23:B36) -> 66086679 | C37: =SUM(C23:C36) -> 67552350 | D37: =[5]ESFA!E51 -> 29813541 | E37: =[5]ESFA!C51 -> 25473877 | G37: =[5]ESFA!E51 -> 29813541 | I37: =SUM(I23:I36) -> 53160895
A39: PATRIMONIO
B40: Enero | C40: Febrero | D40: Marzo | E40: Abril | G40: Mayo | I40: Junio | K40: Julio | L40: Agosto
A41: Reserva de ley 675 2001 | B41: ='ESFA feb 2025'!C57 -> 8861215.9 | C41: ='ESFA feb 2025'!E57 -> 8574200.9 | D41: ='ESFA abril 2025'!E55 -> 9148230.1 | E41: ='ESFA abril 2025'!C55 -> 9476606.9 | G41: ='ESFA MAY 2025'!C56 -> 9773964.9 | I41: ='ESFA JUN 2025'!C56 -> 10053730
A43: Resultados del presente ejercicio | B43: ='ESFA feb 2025'!C59 -> 563544.11 | C43: ='ESFA feb 2025'!E59 -> 56589.37 | D43: ='ESFA abril 2025'!E57 -> 595837.69 | E43: ='ESFA abril 2025'!C57 -> 6876070.4 | G43: ='ESFA MAY 2025'!C58 -> 7171827.1 | I43: ='ESFA JUN 2025'!C58 -> 10687867
A45: Excedente- reconocimiento talud | B45: ='ESFA feb 2025'!E58 -> 7100905.5 | C45: ='ESFA feb 2025'!C58 -> 7100905.5 | D45: ='ESFA abril 2025'!E58 -> -49920464 | E45: ='ESFA abril 2025'!C56 -> 0 | G45: ='ESFA MAY 2025'!C59 -> 248452.74 | I45: ='ESFA JUN 2025'!C59 -> 248452.74
E46: =E41+E43+E45 -> 16352677 | G46: =G41+G43+G45 -> 17194245 | I46: =SUM(I41:I45) -> 20990049
B47: =SUM(B41:B45) -> 16525665 | C47: =SUM(C41:C45) -> 15731696 | D47: =SUM(D41:D45) -> -40176396
E50: 45748 | G50: 45778 | I50: 45809
A51: ACTIVO | E51: =E17 -> 45098563 | G51: =G17 -> 79344897 | I51: =I17 -> 82701066
A52: PASIVO | E52: =E37 -> 25473877 | G52: =G37 -> 29813541 | I52: =I37 -> 53160895
A53: PATRIMONIO | E53: =E46 -> 16352677 | G53: =G46 -> 17194245 | I53: =I46 -> 20990049

Sheet GRAF ESTAD RESUL2025

Sheet Sub-Sobre ejec agost 2025
B1: URBANIZACION MONTEVERDI P.H. NIT 900.317.187.5
B3: ESTADO INTEGRAL DE RESULTADOS A 31 DEAGOSTO DE 2025
A5: 1 | B5: 8 | C5: PPTO ANUAL2025 | D5: PTTO.2025 | E5: REAL ENE. | F5: REAL FEB | G5: REAL MARZO | H5: REAL ABR | I5: REAL MAY | J5: REAL JUN | K5: REAL JUL | L5: REAL AGO | M5: REAL SEP | N5: REAL OCT | O5: REAL NOV | P5: REAL DIC | Q5: EJECUTADO ACUMUL. | R5: PTTO. ACUMUL. | S5: SOBRE O SUBEJECUCION | T5: VARIACION
B6: Aseo Y Piscina (Personal) | C6: 33199438 | D6: 2766619.9 | E6: 2766619 | F6: 2766619 | G6: 2766619 | H6: 2766619 | I6: 2827988 | J6: 2766620 | K6: 2766620 | L6: 2766620 | Q6: 22194324 | R6: 22132959 | S6: -61365.12 | T6: -61365.12 | V6: 41701001 | W6: CUOTAS DE ADMINISTRACION | X6: -208149088 | Y6: 0 | Z6: 29735584 | AA6: -237884672
B7: Aseo (Insumos) | C7: 1260000 | D7: 105000 | E7: 143550 | F7: 235199 | G7: 220474 | H7: 175110 | I7: 120400 | J7: 95350 | K7: 115100 | L7: 77500 | Q7: 1182683 | R7: 840000 | S7: -342683 | T7: -342683 | V7: 42 | W7: NO OPERACIONALES | X7: -3520084.6 | Y7: 0 | Z7: 519706.7 | AA7: -4039791.3
B8: Dotacion | C8: 0 | D8: 0 | E8: 0 | F8: 350000 | Q8: 350000 | R8: 0 | S8: -350000 | T8: -350000 | V8: 42104001 | W8: DESCUENTO POR PRONTO PAGO | X8: -1872704 | Y8: 0 | Z8: 262103 | AA8: -2134807
B9: Sistema De Seguridad Prev | C9: 1341006.2 | D9: 111750.52 | E9: 640110 | F9: 111750 | G9: 111750 | H9: 111750 | I9: 111750 | J9: 111750 | K9: 111750 | L9: 111750 | Q9: 1422360 | R9: 894004.16 | S9: -528355.84 | T9: -528355.84 | V9: 42950502 | W9: AJUSTE AL PESO | X9: -755 | Y9: 0 | Z9: 0 | AA9: -755
B10: Reserva Estatutaria 1% Del Ppto (De Ley) | C10: 3533088 | D10: 294424 | E10: 287015 | F10: 287015 | G10: 287015 | H10: 328376 | I10: 282699 | J10: 294424 | K10: 297358 | L10: 297356 | Q10: 2361258 | R10: 2355392 | S10: -5866 | T10: -5866 | V10: 511030 | W10: ASESORIA FINANCIERA | X10: 4275423 | Y10: 534452 | Z10: 0 | AA10: 4809875
B11: Celebraciones -Navidad | C11: 0 | D11: 0 | E11: 0 | F11: 0 | G11: 0 | H11: 0 | I11: 0 | J11: 179214 | K11: 0 | L11: 0 | Q11: 179214 | R11: 0 | S11: -179214 | T11: -179214 | V11: 511515 | W11: A LA PROPIEDAD RAIZ | X11: 1001500 | Y11: 0 | Z11: 0 | AA11: 1001500
B12: Asamblea (Ley) | C12: 0 | D12: 0 | E12: 0 | F12: 0 | G12: 338650 | H12: 0 | I12: 176715 | J12: 0 | K12: 0 | L12: 0 | M12: 0 | N12: 0 | O12: 0 | P12: 0 | Q12: 515365 | R12: 0 | S12: -515365 | T12: -515365 | V12: 51151502 | W12: TASA SEGURIDAD | X12: 1001500 | Y12: 0 | Z12: 0 | AA12: 1001500
B13: Total Convivencia | C13: 0 | D13: 0 | E13: 0 | F13: 0 | G13: 338650 | H13: 0 | I13: 176715 | J13: 179214 | K13: 0 | L13: 0 | M13: 0 | N13: 0 | O13: 0 | P13: 0 | Q13: 694579 | R13: 0 | S13: -694579 | T13: -694579 | V13: 5130 | W13: SEGUROS | X13: 9564823 | Y13: 1443315 | Z13: 0 | AA13: 11008138
B14: Fumigación | C14: 2568001.5 | D14: 214000.12 | E14: 0 | F14: 0 | G14: 595450 | H14: 0 | I14: 781652 | L14: 781652 | Q14: 2158754 | R14: 1712001 | S14: -446753 | T14: -446753 | V14: 51302501 | W14: SEGURO ZONAS COMUNES | X14: 9564823 | Y14: 1443315 | Z14: 0 | AA14: 11008138
B15: Acueducto Y Alcantarillado | C15: 3500000 | D15: 291666.67 | E15: 129706 | F15: 233099 | G15: 303870 | H15: 205744 | I15: 217588 | J15: 249565 | K15: 956190 | L15: 380094 | Q15: 2675856 | R15: 2333333.3 | S15: -342522.67 | T15: -342522.67 | V15: 513505 | W15: ASEO Y VIGILANCIA | X15: 113623094 | Y15: 16176904 | Z15: 0 | AA15: 129799998
B16: Tasa De Aseo | C16: 604000 | D16: 50333.333 | E16: 50100 | F16: 50115 | G16: 56102 | H16: 56070 | I16: 56076 | J16: 55806 | K16: 55760 | L16: 56144 | Q16: 436173 | R16: 402666.67 | S16: -33506.333 | T16: -33506.333 | V16: 51350501 | W16: SERVICIOS DE VIGILANCIA | X16: 93815361 | Y16: 13354140 | Z16: 0 | AA16: 107169501
B17: Telefonía E Internet | C17: 800000 | D17: 66666.667 | E17: 87582 | F17: 100988 | G17: 100988 | H17: 100988 | I17: 100988 | J17: 100988 | K17: 100988 | L17: 100988 | Q17: 794498 | R17: 533333.33 | S17: -261164.67 | T17: -261164.67 | V17: 51350503 | W17: RECOLECCION DE BASURAS | X17: 380029 | Y17: 56144 | Z17: 0 | AA17: 436173
B18: Tasa de seguridad | I18: 472500 | K18: 529000 | L18: 0 | Q18: 1001500 | R18: 0 | T18: -1001500 | V18: 51351501 | W18: SERVICIOS DE ADMINISTRACION | X18: 17966012 | Y18: 2566487 | Z18: 0 | AA18: 20532499
B19: Administración | C19: 30797847 | D19: 2566487.2 | E19: 2343824 | F19: 2343824 | G19: 2343824 | H19: 3235079 | I19: 2566487 | J19: 2566487 | K19: 2566487 | L19: 2566487 | Q19: 20532499 | R19: 20531898 | S19: -601 | T19: -601 | V19: 513521 | W19: SISTEMA SS-SGT | X19: 346700 | Y19: 0 | Z19: 0 | AA19: 346700
B20: Informacion Exogena Y Niff | C20: 534465 | D20: 44538.75 | E20: 0 | F20: 0 | G20: 0 | H20: 0 | I20: 0 | J20: 534565 | K20: 0 | L20: 0 | Q20: 534565 | R20: 356310 | S20: -178255 | T20: -178255 | V20: 513525 | W20: ACUEDUCTO Y ALCANTARILLADO | X20: 2296612 | Y20: 380094 | Z20: 0 | AA20: 2676706
B21: Facturación | C21: 603903 | D21: 50325.25 | E21: 50344 | F21: 50344 | G21: 50344 | H21: 50344 | I21: 50344 | J21: 50344 | K21: 50344 | L21: 50344 | Q21: 402752 | R21: 402602 | S21: -150 | T21: -150 | V21: 51352501 | W21: ACUEDUCTO Y ALCANTARILLADO | X21: 2296612 | Y21: 380094 | Z21: 0 | AA21: 2676706
F22: GABRIELA MUÑOZ MOLINA | V22: 519525 | W22: ELEMENTOS DE ASEO Y CAFETERIA | X22: 1238793 | Y22: 77500 | Z22: 0 | AA22: 1316293
B23: 8 | C23: PPTO ANUAL2025 | D23: PTTO.2025 | E23: REAL ENE. | F23: REAL FEB | G23: REAL MARZO | H23: REAL ABR | I23: REAL MAY | J23: REAL JUN | K23: REAL JUL | L23: REAL AGO | M23: REAL SEP | N23: REAL OCT | O23: REAL NOV | P23: REAL DIC | Q23: EJECUTADO ACUMUL. | R23: PTTO. ACUMUL. | S23: SOBRE O SUBEJECUCION | T23: VARIACION
B24: Zonas Comunes General | C24: 10500000 | D24: 875000 | E24: 1581421 | F24: 0 | G24: 523837 | H24: 338825 | I24: 167100 | J24: 1050763 | K24: 1107390 | L24: 1519560 | Q24: 6288896 | R24: 7000000 | S24: 711104 | T24: 711104 | V24: 519550 | W24: IMPLEMENTACION | X24: 837137 | Y24: 200687 | Z24: 0 | AA24: 1037824
B25: Mantenimento Electrico | C25: 1800000 | D25: 150000 | E25: 229300 | F25: 104000 | G25: 366738 | I25: 6000 | J25: 122000 | K25: 0 | L25: 80000 | Q25: 908038 | R25: 1200000 | S25: 291962 | T25: 291962 | V25: 51955001 | W25: IMPLEMENTACION SS-SSGT | X25: 781887 | Y25: 200687 | Z25: 0 | AA25: 982574
B26: Piscina-Zona Húmeda-Turco | C26: 11900000 | D26: 991666.67 | E26: 823302 | F26: 1301779 | G26: 611281 | H26: 203409 | I26: 984464 | J26: 203409 | K26: 203409 | L26: 801889 | Q26: 5132942 | R26: 7933333.3 | S26: 2800391.3 | T26: 2800391.3 | V26: 51955003 | W26: PEMIRS | X26: 55250 | Y26: 0 | Z26: 0 | AA26: 55250
B27: Puerta Vehicular Y Peatonal | C27: 590000 | D27: 49166.667 | E27: 0 | F27: 140000 | G27: 0 | L27: 140000 | Q27: 280000 | R27: 393333.33 | S27: 113333.33 | T27: 113333.33 | V27: 519595 | W27: OTROS | X27: 692698.88 | Y27: 0 | Z27: 0 | AA27: 692698.88
B28: Gimnasio | C28: 2429980 | D28: 202498.33 | E28: 246330 | F28: 0 | G28: 749700 | I28: 246330 | J28: 0 | K28: 238000 | L28: 0 | Q28: 1480360 | R28: 1619986.7 | S28: 139626.67 | T28: 139626.67 | V28: 51959503 | W28: GASTOS ASAMBLEA | X28: 338650 | Y28: 0 | Z28: 0 | AA28: 338650
B29: Vigilancia Privada | C29: 1.5883039e+08 | D29: 13235866 | E29: 13136493 | F29: 13136493 | G29: 13136494 | H29: 13136494 | I29: 13136494 | J29: 13136493 | K29: 13244869 | L29: 13354140 | Q29: 105417970 | R29: 1.0588693e+08 | S29: 468958.1 | T29: 468958.1 | V29: 519920 | W29: FONDO DE IMPREVISTOS | X29: 2063902 | Y29: 297356 | Z29: 0 | AA29: 2361258
B30: Refuerzo Vigilancia | C30: 3977071 | D30: 331422.58 | F30: 1751531 | Q30: 1751531 | R30: 2651380.7 | T30: 899849.67 | V30: 51992001 | W30: FONDO IMPREV LEY 675 | X30: 2063902 | Y30: 297356 | Z30: 0 | AA30: 2361258
B31: Seguro Zonas Comunes | C31: 17577558 | D31: 1464796.5 | E31: 1357394 | F31: 904930 | G31: 1443315 | H31: 1486277 | I31: 1486277 | J31: 1443315 | K31: 1443315 | L31: 1443315 | Q31: 11008138 | R31: 11718372 | S31: 710234 | T31: 710234 | V31: 53 | W31: NO OPERACIONALES | X31: 1193975.7 | Y31: 206789.6 | Z31: 0 | AA31: 1400765.3
B32: Sistema De Seg.Repuestos | C32: 1950000 | D32: 162500 | E32: 0 | F32: 0 | G32: 0 | I32: 555730 | J32: 142800 | K32: 0 | L32: 0 | Q32: 698530 | R32: 1300000 | T32: 601470 | V32: 530505 | W32: GASTOS BANCARIOS | X32: 1187594.5 | Y32: 206789.6 | Z32: 0 | AA32: 1394384.1
B33: Sg-Sst, Requisto De Ley | C33: 1910000 | D33: 159166.67 | E33: 0 | F33: 0 | G33: 288000 | H33: 50000 | I33: 305387 | K33: 346700 | L33: 200687 | Q33: 1190774 | R33: 1273333.3 | S33: 82559.333 | T33: 82559.333 | V33: 53050501 | W33: COBRO SERVICIOS DE RECAUDO | X33: 658414.54 | Y33: 22193.5 | Z33: 0 | AA33: 680608.04
B34: Extintores (Recarga) | C34: 372000 | D34: 31000 | E34: 0 | F34: 0 | G34: 0 | K34: 0 | L34: 0 | Q34: 0 | R34: 248000 | S34: #REF! | T34: 248000 | V34: 53050502 | W34: COMISION PAGO A PROVEEDORES | X34: 0 | Y34: 83538 | Z34: 0 | AA34: 83538
B35: Planes De Ley Emerg, Trat Datos | C35: 740000 | D35: 61666.667 | F35: 138500 | G35: 0 | L35: 0 | Q35: 138500 | R35: 493333.33 | S35: 354833.33 | T35: 354833.33 | V35: 53050503 | W35: MANEJO SUCURSAL VIRTUAL | X35: 529180 | Y35: 101058.1 | Z35: 0 | AA35: 630238.1
B36: Energía | C36: 38237500 | D36: 3186458.3 | E36: 3189683.9 | F36: 2628727 | G36: 2554892 | H36: 2640861 | I36: 3098024 | J36: 2908845 | K36: 2964954 | L36: 2551875 | Q36: 22537862 | R36: 25491667 | S36: 2953804.8 | T36: 2953804.8
B37: SGIRS Pmirs Ley | C37: 1211856 | D37: 100988 | E37: 0 | F37: 0 | G37: 55250 | H37: 0 | I37: 0 | Q37: 55250 | R37: 807904 | T37: 752654
B38: Corte Cesped Y Mto Jardines Z. Comun | C38: 16250400 | D38: 1354200 | E38: 1354200 | F38: 1354200 | G38: 1354200 | H38: 1354200 | I38: 1354200 | K38: 1354200 | L38: 2279100 | Q38: 10404300 | R38: 10833600 | S38: 429300 | T38: 429300
B39: Contabilidad | C39: 6413421 | D39: 534451.75 | E39: 488080 | F39: 488080 | G39: 627190 | H39: 534352 | I39: 534352 | J39: 534352 | K39: 534452 | L39: 534452 | Q39: 4275310 | R39: 4275614 | S39: 304 | T39: 304
B40: Útiles,Papelería -Comunicación | C40: 200000 | D40: 16666.667 | E40: 0 | F40: 0 | G40: 10000 | H40: 10000 | I40: 0 | J40: 0 | K40: 0 | L40: 0 | Q40: 20000 | R40: 133333.33 | S40: 113333.33 | T40: 113333.33
B41: Cafeteria | C41: 360000 | D41: 30000 | E41: 0 | F41: 0 | G41: 26640 | H41: 4390 | I41: 27030 | J41: 0 | K41: 75550 | L41: 0 | Q41: 133610 | R41: 240000 | S41: 106390 | T41: 106390
B42: Transporte Trámites | C42: 150000 | D42: 12500 | E42: 0 | F42: 0 | G42: 4500 | H42: 0 | I42: 0 | J42: 0 | K42: 0 | L42: 0 | Q42: 4500 | R42: 100000 | S42: 95500 | T42: 95500
...

Sheet Sobre-sub ejecuciones
B1: URBANIZACION MONTEVERDI P.H. NIT 900.317.187.5
B3: ESTADO INTEGRAL DE RESULTADOS A 31 DE ABRIL DE 2025
A5: 12 | B5: 7 | C5: PPTO ANUAL2025 | D5: PTTO.2025 | E5: REAL ENE. | F5: REAL FEB | G5: REAL MARZO | H5: REAL ABR | I5: REAL MAY | J5: REAL JUN | K5: REAL JUL | L5: REAL AGO | M5: REAL SEP | N5: REAL OCT | O5: REAL NOV | P5: REAL DIC | Q5: PTTO. ACUMUL. | R5: EJECUTADO ACUMUL. | S5: SOBRE O SUBEJECUCION | T5: VARIACION
B6: CUOTAS DE ADMINISTRACION | C6: 353308839 | D6: =+C6/12 -> 29442403 | E6: =-287015+28701567 -> 28414552 | F6: 28414552 | G6: 28414552 | H6: =+H8-H7 -> 32509259 | I6: =29735584-I7 -> 29438226 | J6: =+J8-J7 -> 29438226 | K6: ='ESTAD RESUL JULIO 2025'!K6 -> 29438226 | Q6: =+D6*$B$5 -> 2.0609682e+08 | R6: =SUM(E6:P6) -> 206067593 | S6: =+Q6-R6 -> 29229.75 | T6: =+Q6-R6 -> 29229.75
B7: Ing x Fondo imprevistos | C7: 3533088 | D7: =+C7/12 -> 294424 | E7: 287015 | F7: 287015 | G7: 287015 | H7: 328376 | I7: 297358 | J7: 297358 | K7: ='ESTAD RESUL JULIO 2025'!K7 -> 297358 | Q7: =+D7*$B$5 -> 2060968 | R7: =SUM(E7:P7) -> 2081495 | S7: =+Q7-R7 -> -20527 | T7: =+Q7-R7 -> -20527 | AB7: Presupuesto ordinario acumulado
B8: TOTAL INGRESO OPERACIONAL | C8: =+C6+C7 -> 356841927 | D8: =SUM(D6:D7) -> 29736827 | E8: =SUM(E6:E7) -> 28701567 | F8: =SUM(F6:F7) -> 28701567 | G8: =SUM(G6:G7) -> 28701567 | H8: 32837635 | I8: =+I6+I7 -> 29735584 | J8: 29735584 | K8: ='ESTAD RESUL JULIO 2025'!K8 -> 29735584 | L8: 0 | M8: =SUM(M6:M7) -> 0 | N8: =SUM(N6:N7) -> 0 | O8: =SUM(O6:O7) -> 0 | P8: =SUM(P6:P7) -> 0 | Q8: =+D8*$B$5 -> 2.0815779e+08 | R8: =SUM(R6:R7) -> 208149088 | S8: =+Q8-R8 -> 8702.75 | T8: =+Q8-R8 -> 8702.75 | AG8: =281797442-AD10 -> 73639651
B9: Gastos Operacionales
B10: Mantenimiento (Infraestructura) | AB10: Ingresos presupuestados | AD10: =Q8 -> 2.0815779e+08 | AI10: Egresos operacionales presupuestados | AL10: =Q57 -> 2.0815779e+08
B11: Aseo Y Piscina (Personal) | C11: 33199438 | D11: 2766619.9 | E11: 2766619 | F11: 2766619 | G11: 2766619 | H11: 2766619 | I11: 2827988 | J11: 2766620 | K11: 2766620 | Q11: 19366339 | R11: 19427704 | S11: -61364.98 | T11: -61364.98 | U11: Transporte hidrolavadora | AB11: Ingresos ejecutados | AD11: =R8 -> 208149088 | AI11: Egresos operacionales reales | AL11: =R57 -> 1.9956645e+08
B12: Aseo (Insumos) | C12: 1260000 | D12: 105000 | E12: 143550 | F12: 235199 | G12: 220474 | H12: 175110 | I12: 120400 | J12: 95350 | K12: 115100 | Q12: 735000 | R12: 1105183 | S12: -370183 | T12: -370183 | U12: Insumos para recuperar cancha squash | AB12: Ingresos marginales | AD12: =AD10-AD11 -> 8702.75 | AI12: Diferencia | AL12: =AL10-AL11 -> 8591337.3
B13: Zonas Comunes General | C13: 10500000 | D13: 875000 | E13: 1581421 | F13: 0 | G13: 523837 | H13: 338825 | I13: 167100 | J13: 1050763 | K13: 1107390 | Q13: 6125000 | R13: 4769336 | S13: 1355664 | T13: 1355664
B14: Mantenimento Electrico | C14: 1800000 | D14: 150000 | E14: 229300 | F14: 104000 | G14: 366738 | I14: 6000 | J14: 122000 | K14: 0 | Q14: 1050000 | R14: 828038 | S14: 221962 | T14: 221962 | U14: Se ejecuta en la medida que se van necesitando cambiar bombillas
B15: Piscina-Zona Húmeda-Turco | C15: 11900000 | D15: 991666.67 | E15: 823302 | F15: 1301779 | G15: 611281 | H15: 203409 | I15: 984464 | J15: 203409 | K15: 203409 | Q15: 6941666.7 | R15: 4331053 | S15: 2610613.7 | T15: 2610613.7 | U15: Compra de insumos cada 3 meses | AA15: 1 | AI15: 2
B16: Puerta Vehicular Y Peatonal | C16: 590000 | D16: 49166.667 | E16: 0 | F16: 140000 | G16: 0 | K16: 0 | Q16: 344166.67 | R16: 140000 | S16: 204166.67 | T16: 204166.67 | U16: Se realizò mto en agosto
B17: Gimnasio | C17: 2429980 | D17: 202498.33 | E17: 246330 | F17: 0 | G17: 749700 | I17: 246330 | J17: 0 | K17: 238000 | Q17: 1417488.3 | R17: 1480360 | S17: -62871.667 | T17: -62871.667 | U17: cumpliendo
B18: Dotacion | C18: 0 | D18: 0 | E18: 0 | F18: 350000 | K18: 0 | Q18: 0 | R18: 350000 | S18: -350000 | T18: -350000
B19: Total Mantenimiento Y Mejoras | C19: 61679418 | D19: 5139951.5 | E19: 5790522 | F19: 4897597 | G19: 5238649 | H19: 3483963 | I19: 4352282 | J19: 4238142 | K19: 4430519 | L19: 0 | M19: 0 | N19: 0 | O19: 0 | P19: 0 | Q19: 35979661 | R19: 32431674 | S19: 3897986.7 | T19: 3547986.7
B20: Seguridad | D20: 0 | K20: 0
